[2024-03-09T20:18:44.364+0530] {taskinstance.py:1979} INFO - Dependencies all met for dep_context=non-requeueable deps ti=<TaskInstance: python_pipeline_dag.taskB manual__2024-03-09T14:48:37.754150+00:00 [queued]>
[2024-03-09T20:18:44.369+0530] {taskinstance.py:1979} INFO - Dependencies all met for dep_context=requeueable deps ti=<TaskInstance: python_pipeline_dag.taskB manual__2024-03-09T14:48:37.754150+00:00 [queued]>
[2024-03-09T20:18:44.369+0530] {taskinstance.py:2193} INFO - Starting attempt 1 of 1
[2024-03-09T20:18:44.400+0530] {taskinstance.py:2214} INFO - Executing <Task(PythonOperator): taskB> on 2024-03-09 14:48:37.754150+00:00
[2024-03-09T20:18:44.404+0530] {standard_task_runner.py:60} INFO - Started process 24480 to run task
[2024-03-09T20:18:44.410+0530] {standard_task_runner.py:87} INFO - Running: ['airflow', 'tasks', 'run', 'python_pipeline_dag', 'taskB', 'manual__2024-03-09T14:48:37.754150+00:00', '--job-id', '82', '--raw', '--subdir', 'DAGS_FOLDER/execute_python_pipeline.py', '--cfg-path', '/tmp/tmpellrjce0']
[2024-03-09T20:18:44.411+0530] {standard_task_runner.py:88} INFO - Job 82: Subtask taskB
[2024-03-09T20:18:44.475+0530] {task_command.py:423} INFO - Running <TaskInstance: python_pipeline_dag.taskB manual__2024-03-09T14:48:37.754150+00:00 [running]> on host BreakThrough.
[2024-03-09T20:18:44.559+0530] {taskinstance.py:2510} INFO - Exporting env vars: AIRFLOW_CTX_DAG_OWNER='kai' AIRFLOW_CTX_DAG_ID='python_pipeline_dag' AIRFLOW_CTX_TASK_ID='taskB' AIRFLOW_CTX_EXECUTION_DATE='2024-03-09T14:48:37.754150+00:00' AIRFLOW_CTX_TRY_NUMBER='1' AIRFLOW_CTX_DAG_RUN_ID='manual__2024-03-09T14:48:37.754150+00:00'
[2024-03-09T20:18:44.560+0530] {logging_mixin.py:188} INFO - This is task B
[2024-03-09T20:18:44.566+0530] {taskinstance.py:2728} ERROR - Task failed with exception
Traceback (most recent call last):
  File "/home/kai/.local/lib/python3.10/site-packages/airflow/models/taskinstance.py", line 444, in _execute_task
    result = _execute_callable(context=context, **execute_callable_kwargs)
  File "/home/kai/.local/lib/python3.10/site-packages/airflow/models/taskinstance.py", line 414, in _execute_callable
    return execute_callable(context=context, **execute_callable_kwargs)
  File "/home/kai/.local/lib/python3.10/site-packages/airflow/operators/python.py", line 200, in execute
    return_value = self.execute_callable()
  File "/home/kai/.local/lib/python3.10/site-packages/airflow/operators/python.py", line 217, in execute_callable
    return self.python_callable(*self.op_args, **self.op_kwargs)
  File "/home/kai/airflow/dags/execute_python_pipeline.py", line 21, in remove_null_values
    df=pd.read_json(json_data)
  File "/home/kai/.local/lib/python3.10/site-packages/pandas/io/json/_json.py", line 791, in read_json
    json_reader = JsonReader(
  File "/home/kai/.local/lib/python3.10/site-packages/pandas/io/json/_json.py", line 904, in __init__
    data = self._get_data_from_filepath(filepath_or_buffer)
  File "/home/kai/.local/lib/python3.10/site-packages/pandas/io/json/_json.py", line 944, in _get_data_from_filepath
    self.handles = get_handle(
  File "/home/kai/.local/lib/python3.10/site-packages/pandas/io/common.py", line 728, in get_handle
    ioargs = _get_filepath_or_buffer(
  File "/home/kai/.local/lib/python3.10/site-packages/pandas/io/common.py", line 472, in _get_filepath_or_buffer
    raise ValueError(msg)
ValueError: Invalid file path or buffer object type: <class 'NoneType'>
[2024-03-09T20:18:44.569+0530] {taskinstance.py:1149} INFO - Marking task as FAILED. dag_id=python_pipeline_dag, task_id=taskB, execution_date=20240309T144837, start_date=20240309T144844, end_date=20240309T144844
[2024-03-09T20:18:44.599+0530] {standard_task_runner.py:107} ERROR - Failed to execute job 82 for task taskB (Invalid file path or buffer object type: <class 'NoneType'>; 24480)
[2024-03-09T20:18:44.623+0530] {local_task_job_runner.py:234} INFO - Task exited with return code 1
[2024-03-09T20:18:44.635+0530] {taskinstance.py:3309} INFO - 0 downstream tasks scheduled from follow-on schedule check
