[2024-03-12T22:36:59.877+0530] {taskinstance.py:1979} INFO - Dependencies all met for dep_context=non-requeueable deps ti=<TaskInstance: taskflow_branching_operators_dag.read_data manual__2024-03-12T17:06:56.835840+00:00 [queued]>
[2024-03-12T22:36:59.884+0530] {taskinstance.py:1979} INFO - Dependencies all met for dep_context=requeueable deps ti=<TaskInstance: taskflow_branching_operators_dag.read_data manual__2024-03-12T17:06:56.835840+00:00 [queued]>
[2024-03-12T22:36:59.885+0530] {taskinstance.py:2193} INFO - Starting attempt 1 of 1
[2024-03-12T22:36:59.917+0530] {taskinstance.py:2214} INFO - Executing <Task(_PythonDecoratedOperator): read_data> on 2024-03-12 17:06:56.835840+00:00
[2024-03-12T22:36:59.921+0530] {standard_task_runner.py:60} INFO - Started process 279630 to run task
[2024-03-12T22:36:59.925+0530] {standard_task_runner.py:87} INFO - Running: ['airflow', 'tasks', 'run', 'taskflow_branching_operators_dag', 'read_data', 'manual__2024-03-12T17:06:56.835840+00:00', '--job-id', '204', '--raw', '--subdir', 'DAGS_FOLDER/taskflow_branching_operators_dag.py', '--cfg-path', '/tmp/tmpk4383mz_']
[2024-03-12T22:36:59.926+0530] {standard_task_runner.py:88} INFO - Job 204: Subtask read_data
[2024-03-12T22:37:00.097+0530] {task_command.py:423} INFO - Running <TaskInstance: taskflow_branching_operators_dag.read_data manual__2024-03-12T17:06:56.835840+00:00 [running]> on host BreakThrough.
[2024-03-12T22:37:00.327+0530] {taskinstance.py:2510} INFO - Exporting env vars: AIRFLOW_CTX_DAG_OWNER='kai' AIRFLOW_CTX_DAG_ID='taskflow_branching_operators_dag' AIRFLOW_CTX_TASK_ID='read_data' AIRFLOW_CTX_EXECUTION_DATE='2024-03-12T17:06:56.835840+00:00' AIRFLOW_CTX_TRY_NUMBER='1' AIRFLOW_CTX_DAG_RUN_ID='manual__2024-03-12T17:06:56.835840+00:00'
[2024-03-12T22:37:00.332+0530] {logging_mixin.py:188} INFO - This is task A
[2024-03-12T22:37:00.341+0530] {taskinstance.py:2728} ERROR - Task failed with exception
Traceback (most recent call last):
  File "/home/kai/.local/lib/python3.10/site-packages/airflow/models/taskinstance.py", line 444, in _execute_task
    result = _execute_callable(context=context, **execute_callable_kwargs)
  File "/home/kai/.local/lib/python3.10/site-packages/airflow/models/taskinstance.py", line 414, in _execute_callable
    return execute_callable(context=context, **execute_callable_kwargs)
  File "/home/kai/.local/lib/python3.10/site-packages/airflow/decorators/base.py", line 241, in execute
    return_value = super().execute(context)
  File "/home/kai/.local/lib/python3.10/site-packages/airflow/operators/python.py", line 200, in execute
    return_value = self.execute_callable()
  File "/home/kai/.local/lib/python3.10/site-packages/airflow/operators/python.py", line 217, in execute_callable
    return self.python_callable(*self.op_args, **self.op_kwargs)
  File "/home/kai/airflow/dags/taskflow_branching_operators_dag.py", line 25, in read_data
    df=pd.read_csv('dags/datasets/data.csv')
  File "/home/kai/.local/lib/python3.10/site-packages/pandas/io/parsers/readers.py", line 1026, in read_csv
    return _read(filepath_or_buffer, kwds)
  File "/home/kai/.local/lib/python3.10/site-packages/pandas/io/parsers/readers.py", line 620, in _read
    parser = TextFileReader(filepath_or_buffer, **kwds)
  File "/home/kai/.local/lib/python3.10/site-packages/pandas/io/parsers/readers.py", line 1620, in __init__
    self._engine = self._make_engine(f, self.engine)
  File "/home/kai/.local/lib/python3.10/site-packages/pandas/io/parsers/readers.py", line 1880, in _make_engine
    self.handles = get_handle(
  File "/home/kai/.local/lib/python3.10/site-packages/pandas/io/common.py", line 873, in get_handle
    handle = open(
FileNotFoundError: [Errno 2] No such file or directory: 'dags/datasets/data.csv'
[2024-03-12T22:37:00.352+0530] {taskinstance.py:1149} INFO - Marking task as FAILED. dag_id=taskflow_branching_operators_dag, task_id=read_data, execution_date=20240312T170656, start_date=20240312T170659, end_date=20240312T170700
[2024-03-12T22:37:00.385+0530] {standard_task_runner.py:107} ERROR - Failed to execute job 204 for task read_data ([Errno 2] No such file or directory: 'dags/datasets/data.csv'; 279630)
[2024-03-12T22:37:00.421+0530] {local_task_job_runner.py:234} INFO - Task exited with return code 1
[2024-03-12T22:37:00.474+0530] {taskinstance.py:3309} INFO - 0 downstream tasks scheduled from follow-on schedule check
