[2024-03-12T22:38:09.123+0530] {taskinstance.py:1979} INFO - Dependencies all met for dep_context=non-requeueable deps ti=<TaskInstance: taskflow_branching_operators_dag.filter_by_weight manual__2024-03-12T17:07:57.170946+00:00 [queued]>
[2024-03-12T22:38:09.131+0530] {taskinstance.py:1979} INFO - Dependencies all met for dep_context=requeueable deps ti=<TaskInstance: taskflow_branching_operators_dag.filter_by_weight manual__2024-03-12T17:07:57.170946+00:00 [queued]>
[2024-03-12T22:38:09.131+0530] {taskinstance.py:2193} INFO - Starting attempt 1 of 1
[2024-03-12T22:38:09.167+0530] {taskinstance.py:2214} INFO - Executing <Task(_PythonDecoratedOperator): filter_by_weight> on 2024-03-12 17:07:57.170946+00:00
[2024-03-12T22:38:09.170+0530] {standard_task_runner.py:60} INFO - Started process 279760 to run task
[2024-03-12T22:38:09.173+0530] {standard_task_runner.py:87} INFO - Running: ['airflow', 'tasks', 'run', 'taskflow_branching_operators_dag', 'filter_by_weight', 'manual__2024-03-12T17:07:57.170946+00:00', '--job-id', '208', '--raw', '--subdir', 'DAGS_FOLDER/taskflow_branching_operators_dag.py', '--cfg-path', '/tmp/tmpjpvpiovv']
[2024-03-12T22:38:09.174+0530] {standard_task_runner.py:88} INFO - Job 208: Subtask filter_by_weight
[2024-03-12T22:38:09.231+0530] {task_command.py:423} INFO - Running <TaskInstance: taskflow_branching_operators_dag.filter_by_weight manual__2024-03-12T17:07:57.170946+00:00 [running]> on host BreakThrough.
[2024-03-12T22:38:09.318+0530] {taskinstance.py:2510} INFO - Exporting env vars: AIRFLOW_CTX_DAG_OWNER='kai' AIRFLOW_CTX_DAG_ID='taskflow_branching_operators_dag' AIRFLOW_CTX_TASK_ID='filter_by_weight' AIRFLOW_CTX_EXECUTION_DATE='2024-03-12T17:07:57.170946+00:00' AIRFLOW_CTX_TRY_NUMBER='1' AIRFLOW_CTX_DAG_RUN_ID='manual__2024-03-12T17:07:57.170946+00:00'
[2024-03-12T22:38:09.319+0530] {logging_mixin.py:188} INFO - This is task C
[2024-03-12T22:38:09.319+0530] {taskinstance.py:2728} ERROR - Task failed with exception
Traceback (most recent call last):
  File "/home/kai/.local/lib/python3.10/site-packages/airflow/models/taskinstance.py", line 444, in _execute_task
    result = _execute_callable(context=context, **execute_callable_kwargs)
  File "/home/kai/.local/lib/python3.10/site-packages/airflow/models/taskinstance.py", line 414, in _execute_callable
    return execute_callable(context=context, **execute_callable_kwargs)
  File "/home/kai/.local/lib/python3.10/site-packages/airflow/decorators/base.py", line 241, in execute
    return_value = super().execute(context)
  File "/home/kai/.local/lib/python3.10/site-packages/airflow/operators/python.py", line 200, in execute
    return_value = self.execute_callable()
  File "/home/kai/.local/lib/python3.10/site-packages/airflow/operators/python.py", line 217, in execute_callable
    return self.python_callable(*self.op_args, **self.op_kwargs)
  File "/home/kai/airflow/dags/taskflow_branching_operators_dag.py", line 57, in filter_by_weight
    df=pd.read_json(ti.xcom_pull(key='clean_data'))
NameError: name 'ti' is not defined
[2024-03-12T22:38:09.322+0530] {taskinstance.py:1149} INFO - Marking task as FAILED. dag_id=taskflow_branching_operators_dag, task_id=filter_by_weight, execution_date=20240312T170757, start_date=20240312T170809, end_date=20240312T170809
[2024-03-12T22:38:09.356+0530] {standard_task_runner.py:107} ERROR - Failed to execute job 208 for task filter_by_weight (name 'ti' is not defined; 279760)
[2024-03-12T22:38:09.386+0530] {local_task_job_runner.py:234} INFO - Task exited with return code 1
[2024-03-12T22:38:09.402+0530] {taskinstance.py:3309} INFO - 0 downstream tasks scheduled from follow-on schedule check
