[2024-03-10T08:20:43.849+0530] {taskinstance.py:1979} INFO - Dependencies all met for dep_context=non-requeueable deps ti=<TaskInstance: pipeline_variable_dag.branch manual__2024-03-10T02:50:34.157934+00:00 [queued]>
[2024-03-10T08:20:43.855+0530] {taskinstance.py:1979} INFO - Dependencies all met for dep_context=requeueable deps ti=<TaskInstance: pipeline_variable_dag.branch manual__2024-03-10T02:50:34.157934+00:00 [queued]>
[2024-03-10T08:20:43.856+0530] {taskinstance.py:2193} INFO - Starting attempt 1 of 1
[2024-03-10T08:20:43.883+0530] {taskinstance.py:2214} INFO - Executing <Task(BranchPythonOperator): branch> on 2024-03-10 02:50:34.157934+00:00
[2024-03-10T08:20:43.886+0530] {standard_task_runner.py:60} INFO - Started process 100577 to run task
[2024-03-10T08:20:43.890+0530] {standard_task_runner.py:87} INFO - Running: ['airflow', 'tasks', 'run', 'pipeline_variable_dag', 'branch', 'manual__2024-03-10T02:50:34.157934+00:00', '--job-id', '131', '--raw', '--subdir', 'DAGS_FOLDER/execute_branching_variable.py', '--cfg-path', '/tmp/tmpeo4royt4']
[2024-03-10T08:20:43.891+0530] {standard_task_runner.py:88} INFO - Job 131: Subtask branch
[2024-03-10T08:20:43.944+0530] {task_command.py:423} INFO - Running <TaskInstance: pipeline_variable_dag.branch manual__2024-03-10T02:50:34.157934+00:00 [running]> on host BreakThrough.
[2024-03-10T08:20:44.023+0530] {taskinstance.py:2510} INFO - Exporting env vars: AIRFLOW_CTX_DAG_OWNER='kai' AIRFLOW_CTX_DAG_ID='pipeline_variable_dag' AIRFLOW_CTX_TASK_ID='branch' AIRFLOW_CTX_EXECUTION_DATE='2024-03-10T02:50:34.157934+00:00' AIRFLOW_CTX_TRY_NUMBER='1' AIRFLOW_CTX_DAG_RUN_ID='manual__2024-03-10T02:50:34.157934+00:00'
[2024-03-10T08:20:44.024+0530] {logging_mixin.py:188} INFO - branch
[2024-03-10T08:20:44.027+0530] {logging_mixin.py:188} INFO - filter_by_coverage
[2024-03-10T08:20:44.027+0530] {taskinstance.py:2728} ERROR - Task failed with exception
Traceback (most recent call last):
  File "/home/kai/.local/lib/python3.10/site-packages/airflow/models/taskinstance.py", line 444, in _execute_task
    result = _execute_callable(context=context, **execute_callable_kwargs)
  File "/home/kai/.local/lib/python3.10/site-packages/airflow/models/taskinstance.py", line 414, in _execute_callable
    return execute_callable(context=context, **execute_callable_kwargs)
  File "/home/kai/.local/lib/python3.10/site-packages/airflow/operators/python.py", line 234, in execute
    return self.do_branch(context, super().execute(context))
  File "/home/kai/.local/lib/python3.10/site-packages/airflow/operators/python.py", line 200, in execute
    return_value = self.execute_callable()
  File "/home/kai/.local/lib/python3.10/site-packages/airflow/operators/python.py", line 217, in execute_callable
    return self.python_callable(*self.op_args, **self.op_kwargs)
  File "/home/kai/airflow/dags/execute_branching_variable.py", line 33, in branch
    if transform_action.startsWith('filter'):
AttributeError: 'str' object has no attribute 'startsWith'
[2024-03-10T08:20:44.031+0530] {taskinstance.py:1149} INFO - Marking task as FAILED. dag_id=pipeline_variable_dag, task_id=branch, execution_date=20240310T025034, start_date=20240310T025043, end_date=20240310T025044
[2024-03-10T08:20:44.056+0530] {standard_task_runner.py:107} ERROR - Failed to execute job 131 for task branch ('str' object has no attribute 'startsWith'; 100577)
[2024-03-10T08:20:44.063+0530] {local_task_job_runner.py:234} INFO - Task exited with return code 1
[2024-03-10T08:20:44.089+0530] {taskinstance.py:3309} INFO - 0 downstream tasks scheduled from follow-on schedule check
