[2024-03-13T19:58:33.831+0530] {taskinstance.py:1979} INFO - Dependencies all met for dep_context=non-requeueable deps ti=<TaskInstance: taskflow_sql_operations_dag.read_task scheduled__2024-03-12T00:00:00+00:00 [queued]>
[2024-03-13T19:58:33.837+0530] {taskinstance.py:1979} INFO - Dependencies all met for dep_context=requeueable deps ti=<TaskInstance: taskflow_sql_operations_dag.read_task scheduled__2024-03-12T00:00:00+00:00 [queued]>
[2024-03-13T19:58:33.837+0530] {taskinstance.py:2193} INFO - Starting attempt 1 of 1
[2024-03-13T19:58:33.869+0530] {taskinstance.py:2214} INFO - Executing <Task(_PythonDecoratedOperator): read_task> on 2024-03-12 00:00:00+00:00
[2024-03-13T19:58:33.873+0530] {standard_task_runner.py:60} INFO - Started process 291882 to run task
[2024-03-13T19:58:33.877+0530] {standard_task_runner.py:87} INFO - Running: ['airflow', 'tasks', 'run', 'taskflow_sql_operations_dag', 'read_task', 'scheduled__2024-03-12T00:00:00+00:00', '--job-id', '230', '--raw', '--subdir', 'DAGS_FOLDER/taskflow_sql_operations.py', '--cfg-path', '/tmp/tmpwf6q2zst']
[2024-03-13T19:58:33.878+0530] {standard_task_runner.py:88} INFO - Job 230: Subtask read_task
[2024-03-13T19:58:33.939+0530] {task_command.py:423} INFO - Running <TaskInstance: taskflow_sql_operations_dag.read_task scheduled__2024-03-12T00:00:00+00:00 [running]> on host BreakThrough.
[2024-03-13T19:58:34.037+0530] {taskinstance.py:2510} INFO - Exporting env vars: AIRFLOW_CTX_DAG_OWNER='kai' AIRFLOW_CTX_DAG_ID='taskflow_sql_operations_dag' AIRFLOW_CTX_TASK_ID='read_task' AIRFLOW_CTX_EXECUTION_DATE='2024-03-12T00:00:00+00:00' AIRFLOW_CTX_TRY_NUMBER='1' AIRFLOW_CTX_DAG_RUN_ID='scheduled__2024-03-12T00:00:00+00:00'
[2024-03-13T19:58:34.038+0530] {logging_mixin.py:188} INFO - Reading CSV file
[2024-03-13T19:58:34.038+0530] {taskinstance.py:2728} ERROR - Task failed with exception
Traceback (most recent call last):
  File "/home/kai/.local/lib/python3.10/site-packages/airflow/models/taskinstance.py", line 444, in _execute_task
    result = _execute_callable(context=context, **execute_callable_kwargs)
  File "/home/kai/.local/lib/python3.10/site-packages/airflow/models/taskinstance.py", line 414, in _execute_callable
    return execute_callable(context=context, **execute_callable_kwargs)
  File "/home/kai/.local/lib/python3.10/site-packages/airflow/decorators/base.py", line 241, in execute
    return_value = super().execute(context)
  File "/home/kai/.local/lib/python3.10/site-packages/airflow/operators/python.py", line 200, in execute
    return_value = self.execute_callable()
  File "/home/kai/.local/lib/python3.10/site-packages/airflow/operators/python.py", line 217, in execute_callable
    return self.python_callable(*self.op_args, **self.op_kwargs)
  File "/home/kai/airflow/dags/taskflow_sql_operations.py", line 23, in read_csv
    df=pd.read_csv('/home/kai/airflow/dags/datasets/data.csv')
NameError: name 'pd' is not defined
[2024-03-13T19:58:34.047+0530] {taskinstance.py:1149} INFO - Marking task as FAILED. dag_id=taskflow_sql_operations_dag, task_id=read_task, execution_date=20240312T000000, start_date=20240313T142833, end_date=20240313T142834
[2024-03-13T19:58:34.080+0530] {standard_task_runner.py:107} ERROR - Failed to execute job 230 for task read_task (name 'pd' is not defined; 291882)
[2024-03-13T19:58:34.091+0530] {local_task_job_runner.py:234} INFO - Task exited with return code 1
[2024-03-13T19:58:34.108+0530] {taskinstance.py:3309} INFO - 0 downstream tasks scheduled from follow-on schedule check
