[2024-03-09T21:02:09.344+0530] {taskinstance.py:1979} INFO - Dependencies all met for dep_context=non-requeueable deps ti=<TaskInstance: python_pipeline_dag.taskD manual__2024-03-09T15:31:57.548670+00:00 [queued]>
[2024-03-09T21:02:09.350+0530] {taskinstance.py:1979} INFO - Dependencies all met for dep_context=requeueable deps ti=<TaskInstance: python_pipeline_dag.taskD manual__2024-03-09T15:31:57.548670+00:00 [queued]>
[2024-03-09T21:02:09.350+0530] {taskinstance.py:2193} INFO - Starting attempt 1 of 1
[2024-03-09T21:02:09.384+0530] {taskinstance.py:2214} INFO - Executing <Task(PythonOperator): taskD> on 2024-03-09 15:31:57.548670+00:00
[2024-03-09T21:02:09.391+0530] {standard_task_runner.py:60} INFO - Started process 35623 to run task
[2024-03-09T21:02:09.394+0530] {standard_task_runner.py:87} INFO - Running: ['airflow', 'tasks', 'run', 'python_pipeline_dag', 'taskD', 'manual__2024-03-09T15:31:57.548670+00:00', '--job-id', '88', '--raw', '--subdir', 'DAGS_FOLDER/execute_python_pipeline.py', '--cfg-path', '/tmp/tmpn0h1opfa']
[2024-03-09T21:02:09.396+0530] {standard_task_runner.py:88} INFO - Job 88: Subtask taskD
[2024-03-09T21:02:09.451+0530] {task_command.py:423} INFO - Running <TaskInstance: python_pipeline_dag.taskD manual__2024-03-09T15:31:57.548670+00:00 [running]> on host BreakThrough.
[2024-03-09T21:02:09.541+0530] {taskinstance.py:2510} INFO - Exporting env vars: AIRFLOW_CTX_DAG_OWNER='kai' AIRFLOW_CTX_DAG_ID='python_pipeline_dag' AIRFLOW_CTX_TASK_ID='taskD' AIRFLOW_CTX_EXECUTION_DATE='2024-03-09T15:31:57.548670+00:00' AIRFLOW_CTX_TRY_NUMBER='1' AIRFLOW_CTX_DAG_RUN_ID='manual__2024-03-09T15:31:57.548670+00:00'
[2024-03-09T21:02:09.542+0530] {logging_mixin.py:188} INFO - This is task D
[2024-03-09T21:02:09.543+0530] {taskinstance.py:2728} ERROR - Task failed with exception
Traceback (most recent call last):
  File "/home/kai/.local/lib/python3.10/site-packages/airflow/models/taskinstance.py", line 444, in _execute_task
    result = _execute_callable(context=context, **execute_callable_kwargs)
  File "/home/kai/.local/lib/python3.10/site-packages/airflow/models/taskinstance.py", line 414, in _execute_callable
    return execute_callable(context=context, **execute_callable_kwargs)
  File "/home/kai/.local/lib/python3.10/site-packages/airflow/operators/python.py", line 200, in execute
    return_value = self.execute_callable()
  File "/home/kai/.local/lib/python3.10/site-packages/airflow/operators/python.py", line 217, in execute_callable
    return self.python_callable(*self.op_args, **self.op_kwargs)
  File "/home/kai/airflow/dags/execute_python_pipeline.py", line 34, in groupby_smoker
    json_data=ti.xcom_pull(task_ids='taskB')
NameError: name 'ti' is not defined
[2024-03-09T21:02:09.546+0530] {taskinstance.py:1149} INFO - Marking task as FAILED. dag_id=python_pipeline_dag, task_id=taskD, execution_date=20240309T153157, start_date=20240309T153209, end_date=20240309T153209
[2024-03-09T21:02:09.570+0530] {standard_task_runner.py:107} ERROR - Failed to execute job 88 for task taskD (name 'ti' is not defined; 35623)
[2024-03-09T21:02:09.608+0530] {local_task_job_runner.py:234} INFO - Task exited with return code 1
[2024-03-09T21:02:09.620+0530] {taskinstance.py:3309} INFO - 0 downstream tasks scheduled from follow-on schedule check
