[2024-03-10T08:22:44.191+0530] {taskinstance.py:1979} INFO - Dependencies all met for dep_context=non-requeueable deps ti=<TaskInstance: pipeline_variable_dag.filter_by_coverage manual__2024-03-10T02:52:31.859939+00:00 [queued]>
[2024-03-10T08:22:44.198+0530] {taskinstance.py:1979} INFO - Dependencies all met for dep_context=requeueable deps ti=<TaskInstance: pipeline_variable_dag.filter_by_coverage manual__2024-03-10T02:52:31.859939+00:00 [queued]>
[2024-03-10T08:22:44.198+0530] {taskinstance.py:2193} INFO - Starting attempt 1 of 1
[2024-03-10T08:22:44.227+0530] {taskinstance.py:2214} INFO - Executing <Task(PythonOperator): filter_by_coverage> on 2024-03-10 02:52:31.859939+00:00
[2024-03-10T08:22:44.230+0530] {standard_task_runner.py:60} INFO - Started process 101179 to run task
[2024-03-10T08:22:44.233+0530] {standard_task_runner.py:87} INFO - Running: ['airflow', 'tasks', 'run', 'pipeline_variable_dag', 'filter_by_coverage', 'manual__2024-03-10T02:52:31.859939+00:00', '--job-id', '135', '--raw', '--subdir', 'DAGS_FOLDER/execute_branching_variable.py', '--cfg-path', '/tmp/tmp7bzw4u6o']
[2024-03-10T08:22:44.235+0530] {standard_task_runner.py:88} INFO - Job 135: Subtask filter_by_coverage
[2024-03-10T08:22:44.283+0530] {task_command.py:423} INFO - Running <TaskInstance: pipeline_variable_dag.filter_by_coverage manual__2024-03-10T02:52:31.859939+00:00 [running]> on host BreakThrough.
[2024-03-10T08:22:44.365+0530] {taskinstance.py:2510} INFO - Exporting env vars: AIRFLOW_CTX_DAG_OWNER='kai' AIRFLOW_CTX_DAG_ID='pipeline_variable_dag' AIRFLOW_CTX_TASK_ID='filter_by_coverage' AIRFLOW_CTX_EXECUTION_DATE='2024-03-10T02:52:31.859939+00:00' AIRFLOW_CTX_TRY_NUMBER='1' AIRFLOW_CTX_DAG_RUN_ID='manual__2024-03-10T02:52:31.859939+00:00'
[2024-03-10T08:22:44.366+0530] {logging_mixin.py:188} INFO - filtering by coverage
[2024-03-10T08:22:44.371+0530] {taskinstance.py:2728} ERROR - Task failed with exception
Traceback (most recent call last):
  File "/home/kai/.local/lib/python3.10/site-packages/airflow/models/taskinstance.py", line 444, in _execute_task
    result = _execute_callable(context=context, **execute_callable_kwargs)
  File "/home/kai/.local/lib/python3.10/site-packages/airflow/models/taskinstance.py", line 414, in _execute_callable
    return execute_callable(context=context, **execute_callable_kwargs)
  File "/home/kai/.local/lib/python3.10/site-packages/airflow/operators/python.py", line 200, in execute
    return_value = self.execute_callable()
  File "/home/kai/.local/lib/python3.10/site-packages/airflow/operators/python.py", line 217, in execute_callable
    return self.python_callable(*self.op_args, **self.op_kwargs)
  File "/home/kai/airflow/dags/execute_branching_variable.py", line 43, in filter_by_coverage
    df=pd.read.json(json_data)
AttributeError: module 'pandas' has no attribute 'read'
[2024-03-10T08:22:44.373+0530] {taskinstance.py:1149} INFO - Marking task as FAILED. dag_id=pipeline_variable_dag, task_id=filter_by_coverage, execution_date=20240310T025231, start_date=20240310T025244, end_date=20240310T025244
[2024-03-10T08:22:44.398+0530] {standard_task_runner.py:107} ERROR - Failed to execute job 135 for task filter_by_coverage (module 'pandas' has no attribute 'read'; 101179)
[2024-03-10T08:22:44.407+0530] {local_task_job_runner.py:234} INFO - Task exited with return code 1
[2024-03-10T08:22:44.419+0530] {taskinstance.py:3309} INFO - 0 downstream tasks scheduled from follow-on schedule check
