[2024-03-12T22:39:15.857+0530] {taskinstance.py:1979} INFO - Dependencies all met for dep_context=non-requeueable deps ti=<TaskInstance: taskflow_branching_operators_dag.write_csv manual__2024-03-12T17:09:01.323586+00:00 [queued]>
[2024-03-12T22:39:15.863+0530] {taskinstance.py:1979} INFO - Dependencies all met for dep_context=requeueable deps ti=<TaskInstance: taskflow_branching_operators_dag.write_csv manual__2024-03-12T17:09:01.323586+00:00 [queued]>
[2024-03-12T22:39:15.863+0530] {taskinstance.py:2193} INFO - Starting attempt 1 of 1
[2024-03-12T22:39:15.894+0530] {taskinstance.py:2214} INFO - Executing <Task(_PythonDecoratedOperator): write_csv> on 2024-03-12 17:09:01.323586+00:00
[2024-03-12T22:39:15.898+0530] {standard_task_runner.py:60} INFO - Started process 279913 to run task
[2024-03-12T22:39:15.901+0530] {standard_task_runner.py:87} INFO - Running: ['airflow', 'tasks', 'run', 'taskflow_branching_operators_dag', 'write_csv', 'manual__2024-03-12T17:09:01.323586+00:00', '--job-id', '213', '--raw', '--subdir', 'DAGS_FOLDER/taskflow_branching_operators_dag.py', '--cfg-path', '/tmp/tmp4r_1ukup']
[2024-03-12T22:39:15.903+0530] {standard_task_runner.py:88} INFO - Job 213: Subtask write_csv
[2024-03-12T22:39:15.950+0530] {task_command.py:423} INFO - Running <TaskInstance: taskflow_branching_operators_dag.write_csv manual__2024-03-12T17:09:01.323586+00:00 [running]> on host BreakThrough.
[2024-03-12T22:39:16.037+0530] {taskinstance.py:2510} INFO - Exporting env vars: AIRFLOW_CTX_DAG_OWNER='kai' AIRFLOW_CTX_DAG_ID='taskflow_branching_operators_dag' AIRFLOW_CTX_TASK_ID='write_csv' AIRFLOW_CTX_EXECUTION_DATE='2024-03-12T17:09:01.323586+00:00' AIRFLOW_CTX_TRY_NUMBER='1' AIRFLOW_CTX_DAG_RUN_ID='manual__2024-03-12T17:09:01.323586+00:00'
[2024-03-12T22:39:16.038+0530] {logging_mixin.py:188} INFO - This is task D
[2024-03-12T22:39:16.038+0530] {taskinstance.py:2728} ERROR - Task failed with exception
Traceback (most recent call last):
  File "/home/kai/.local/lib/python3.10/site-packages/airflow/models/taskinstance.py", line 444, in _execute_task
    result = _execute_callable(context=context, **execute_callable_kwargs)
  File "/home/kai/.local/lib/python3.10/site-packages/airflow/models/taskinstance.py", line 414, in _execute_callable
    return execute_callable(context=context, **execute_callable_kwargs)
  File "/home/kai/.local/lib/python3.10/site-packages/airflow/decorators/base.py", line 241, in execute
    return_value = super().execute(context)
  File "/home/kai/.local/lib/python3.10/site-packages/airflow/operators/python.py", line 200, in execute
    return_value = self.execute_callable()
  File "/home/kai/.local/lib/python3.10/site-packages/airflow/operators/python.py", line 217, in execute_callable
    return self.python_callable(*self.op_args, **self.op_kwargs)
  File "/home/kai/airflow/dags/taskflow_branching_operators_dag.py", line 67, in write_csv
    data=ti.xcom_pull(key='filtered_data')
NameError: name 'ti' is not defined
[2024-03-12T22:39:16.041+0530] {taskinstance.py:1149} INFO - Marking task as FAILED. dag_id=taskflow_branching_operators_dag, task_id=write_csv, execution_date=20240312T170901, start_date=20240312T170915, end_date=20240312T170916
[2024-03-12T22:39:16.072+0530] {standard_task_runner.py:107} ERROR - Failed to execute job 213 for task write_csv (name 'ti' is not defined; 279913)
[2024-03-12T22:39:16.115+0530] {local_task_job_runner.py:234} INFO - Task exited with return code 1
[2024-03-12T22:39:16.126+0530] {taskinstance.py:3309} INFO - 0 downstream tasks scheduled from follow-on schedule check
